Traceback (most recent call last):
  File "/work/nrisse/anaconda3/envs/pyac3/lib/python3.9/site-packages/jupyter_cache/executors/utils.py", line 51, in single_nb_execution
    executenb(
  File "/work/nrisse/anaconda3/envs/pyac3/lib/python3.9/site-packages/nbclient/client.py", line 1117, in execute
    return NotebookClient(nb=nb, resources=resources, km=km, **kwargs).execute()
  File "/work/nrisse/anaconda3/envs/pyac3/lib/python3.9/site-packages/nbclient/util.py", line 78, in wrapped
    return just_run(coro(*args, **kwargs))
  File "/work/nrisse/anaconda3/envs/pyac3/lib/python3.9/site-packages/nbclient/util.py", line 57, in just_run
    return loop.run_until_complete(coro)
  File "/work/nrisse/anaconda3/envs/pyac3/lib/python3.9/asyncio/base_events.py", line 642, in run_until_complete
    return future.result()
  File "/work/nrisse/anaconda3/envs/pyac3/lib/python3.9/site-packages/nbclient/client.py", line 558, in async_execute
    await self.async_execute_cell(
  File "/work/nrisse/anaconda3/envs/pyac3/lib/python3.9/site-packages/nbclient/client.py", line 862, in async_execute_cell
    self._check_raise_for_error(cell, exec_reply)
  File "/work/nrisse/anaconda3/envs/pyac3/lib/python3.9/site-packages/nbclient/client.py", line 765, in _check_raise_for_error
    raise CellExecutionError.from_cell_and_msg(cell, exec_reply_content)
nbclient.exceptions.CellExecutionError: An error occurred while executing the following cell:
------------------
fig, axes = plt.subplots(1, 3, sharey=True, sharex=True)

ax = {'ACLOUD': axes[0], 'AFLUX': axes[1], 'MOSAiC-ACA': axes[2]}

kwargs = dict(s=1, color='red', alpha=0.4)
for mission, sondes in ds_dict.items():
    
    ax[mission].set_title(mission)
    
    for sonde_id, params in ds_dict[mission].items():

        # read dropsonde data
        i_sonde = int(sonde_id[-2:])
        ds = cat['P5']['DROPSONDES'][params['flight_id']](i_sonde=i_sonde).to_dask()

        ax[mission].scatter(ds.Temp_recon, ds.GPS_Alt, **kwargs)

axes[0].set_ylabel('Altitude [m]')
axes[0].set_xlabel('Temperature [Â°C]')
   
plt.show()
------------------

[0;31m---------------------------------------------------------------------------[0m
[0;31mValueError[0m                                Traceback (most recent call last)
[0;32m/tmp/ipykernel_776625/2378587517.py[0m in [0;36m<module>[0;34m[0m
[1;32m     11[0m [0;34m[0m[0m
[1;32m     12[0m         [0;31m# read dropsonde data[0m[0;34m[0m[0;34m[0m[0;34m[0m[0m
[0;32m---> 13[0;31m         [0mi_sonde[0m [0;34m=[0m [0mint[0m[0;34m([0m[0msonde_id[0m[0;34m[[0m[0;34m-[0m[0;36m2[0m[0;34m:[0m[0;34m][0m[0;34m)[0m[0;34m[0m[0;34m[0m[0m
[0m[1;32m     14[0m         [0mds[0m [0;34m=[0m [0mcat[0m[0;34m[[0m[0;34m'P5'[0m[0;34m][0m[0;34m[[0m[0;34m'DROPSONDES'[0m[0;34m][0m[0;34m[[0m[0mparams[0m[0;34m[[0m[0;34m'flight_id'[0m[0;34m][0m[0;34m][0m[0;34m([0m[0mi_sonde[0m[0;34m=[0m[0mi_sonde[0m[0;34m)[0m[0;34m.[0m[0mto_dask[0m[0;34m([0m[0;34m)[0m[0;34m[0m[0;34m[0m[0m
[1;32m     15[0m [0;34m[0m[0m

[0;31mValueError[0m: invalid literal for int() with base 10: 'AD'
ValueError: invalid literal for int() with base 10: 'AD'

