Traceback (most recent call last):
  File "/usr/local/lib/python3.8/dist-packages/jupyter_cache/executors/utils.py", line 51, in single_nb_execution
    executenb(
  File "/usr/local/lib/python3.8/dist-packages/nbclient/client.py", line 1112, in execute
    return NotebookClient(nb=nb, resources=resources, km=km, **kwargs).execute()
  File "/usr/local/lib/python3.8/dist-packages/nbclient/util.py", line 74, in wrapped
    return just_run(coro(*args, **kwargs))
  File "/usr/local/lib/python3.8/dist-packages/nbclient/util.py", line 53, in just_run
    return loop.run_until_complete(coro)
  File "/usr/lib/python3.8/asyncio/base_events.py", line 616, in run_until_complete
    return future.result()
  File "/usr/local/lib/python3.8/dist-packages/nbclient/client.py", line 553, in async_execute
    await self.async_execute_cell(
  File "/usr/local/lib/python3.8/dist-packages/nbclient/client.py", line 857, in async_execute_cell
    self._check_raise_for_error(cell, exec_reply)
  File "/usr/local/lib/python3.8/dist-packages/nbclient/client.py", line 760, in _check_raise_for_error
    raise CellExecutionError.from_cell_and_msg(cell, exec_reply_content)
nbclient.exceptions.CellExecutionError: An error occurred while executing the following cell:
------------------
ds_hatpro = cat['MOSAiC-ACA']['P5']['HATPRO']['MOSAiC-ACA_P5_RF11'](user=ac3cloud_username,password=ac3cloud_password).to_dask()
ds_hatpro
------------------

[0;31m---------------------------------------------------------------------------[0m
[0;31mTypeError[0m                                 Traceback (most recent call last)
[0;32m/tmp/ipykernel_613005/597991908.py[0m in [0;36m<module>[0;34m[0m
[0;32m----> 1[0;31m [0mds_hatpro[0m [0;34m=[0m [0mcat[0m[0;34m[[0m[0;34m'MOSAiC-ACA'[0m[0;34m][0m[0;34m[[0m[0;34m'P5'[0m[0;34m][0m[0;34m[[0m[0;34m'HATPRO'[0m[0;34m][0m[0;34m[[0m[0;34m'MOSAiC-ACA_P5_RF11'[0m[0;34m][0m[0;34m([0m[0muser[0m[0;34m=[0m[0mac3cloud_username[0m[0;34m,[0m[0mpassword[0m[0;34m=[0m[0mac3cloud_password[0m[0;34m)[0m[0;34m.[0m[0mto_dask[0m[0;34m([0m[0;34m)[0m[0;34m[0m[0;34m[0m[0m
[0m[1;32m      2[0m [0mds_hatpro[0m[0;34m[0m[0;34m[0m[0m

[0;32m/usr/local/lib/python3.8/dist-packages/intake/source/base.py[0m in [0;36mconfigure_new[0;34m(self, **kwargs)[0m
[1;32m    252[0m         """
[1;32m    253[0m         [0;32mif[0m [0mself[0m[0;34m.[0m[0m_entry[0m [0;32mis[0m [0;32mnot[0m [0;32mNone[0m[0;34m:[0m[0;34m[0m[0;34m[0m[0m
[0;32m--> 254[0;31m             [0mobj[0m [0;34m=[0m [0mself[0m[0;34m.[0m[0m_entry[0m[0;34m([0m[0;34m**[0m[0mkwargs[0m[0;34m)[0m[0;34m[0m[0;34m[0m[0m
[0m[1;32m    255[0m             [0mobj[0m[0;34m.[0m[0m_entry[0m [0;34m=[0m [0mself[0m[0;34m.[0m[0m_entry[0m[0;34m[0m[0;34m[0m[0m
[1;32m    256[0m             [0;32mreturn[0m [0mobj[0m[0;34m[0m[0;34m[0m[0m

[0;32m/usr/local/lib/python3.8/dist-packages/intake/catalog/entry.py[0m in [0;36m__call__[0;34m(self, persist, **kwargs)[0m
[1;32m     75[0m             [0;32mraise[0m [0mValueError[0m[0;34m([0m[0;34m'Persist value (%s) not understood'[0m [0;34m%[0m [0mpersist[0m[0;34m)[0m[0;34m[0m[0;34m[0m[0m
[1;32m     76[0m         [0mpersist[0m [0;34m=[0m [0mpersist[0m [0;32mor[0m [0mself[0m[0;34m.[0m[0m_pmode[0m[0;34m[0m[0;34m[0m[0m
[0;32m---> 77[0;31m         [0ms[0m [0;34m=[0m [0mself[0m[0;34m.[0m[0mget[0m[0;34m([0m[0;34m**[0m[0mkwargs[0m[0;34m)[0m[0;34m[0m[0;34m[0m[0m
[0m[1;32m     78[0m         [0;32mif[0m [0mpersist[0m [0;34m!=[0m [0;34m'never'[0m [0;32mand[0m [0ms[0m[0;34m.[0m[0mhas_been_persisted[0m[0;34m:[0m[0;34m[0m[0;34m[0m[0m
[1;32m     79[0m             [0;32mfrom[0m [0;34m.[0m[0;34m.[0m[0mcontainer[0m[0;34m.[0m[0mpersist[0m [0;32mimport[0m [0mstore[0m[0;34m[0m[0;34m[0m[0m

[0;32m/usr/local/lib/python3.8/dist-packages/intake/catalog/local.py[0m in [0;36mget[0;34m(self, **user_parameters)[0m
[1;32m    279[0m         [0;34m"""Instantiate the DataSource for the given parameters"""[0m[0;34m[0m[0;34m[0m[0m
[1;32m    280[0m         [0mplugin[0m[0;34m,[0m [0mopen_args[0m [0;34m=[0m [0mself[0m[0;34m.[0m[0m_create_open_args[0m[0;34m([0m[0muser_parameters[0m[0;34m)[0m[0;34m[0m[0;34m[0m[0m
[0;32m--> 281[0;31m         [0mdata_source[0m [0;34m=[0m [0mplugin[0m[0;34m([0m[0;34m**[0m[0mopen_args[0m[0;34m)[0m[0;34m[0m[0;34m[0m[0m
[0m[1;32m    282[0m         [0mdata_source[0m[0;34m.[0m[0mcatalog_object[0m [0;34m=[0m [0mself[0m[0;34m.[0m[0m_catalog[0m[0;34m[0m[0;34m[0m[0m
[1;32m    283[0m         [0mdata_source[0m[0;34m.[0m[0mname[0m [0;34m=[0m [0mself[0m[0;34m.[0m[0mname[0m[0;34m[0m[0;34m[0m[0m

[0;32m/usr/local/lib/python3.8/dist-packages/intake_xarray/netcdf.py[0m in [0;36m__init__[0;34m(self, urlpath, chunks, combine, concat_dim, xarray_kwargs, metadata, path_as_pattern, storage_options, **kwargs)[0m
[1;32m     61[0m         [0;32melse[0m[0;34m:[0m[0;34m[0m[0;34m[0m[0m
[1;32m     62[0m             [0mself[0m[0;34m.[0m[0m_can_be_local[0m [0;34m=[0m [0mfsspec[0m[0;34m.[0m[0mutils[0m[0;34m.[0m[0mcan_be_local[0m[0;34m([0m[0mself[0m[0;34m.[0m[0murlpath[0m[0;34m)[0m[0;34m[0m[0;34m[0m[0m
[0;32m---> 63[0;31m         [0msuper[0m[0;34m([0m[0mNetCDFSource[0m[0;34m,[0m [0mself[0m[0;34m)[0m[0;34m.[0m[0m__init__[0m[0;34m([0m[0mmetadata[0m[0;34m=[0m[0mmetadata[0m[0;34m,[0m [0;34m**[0m[0mkwargs[0m[0;34m)[0m[0;34m[0m[0;34m[0m[0m
[0m[1;32m     64[0m [0;34m[0m[0m
[1;32m     65[0m     [0;32mdef[0m [0m_open_dataset[0m[0;34m([0m[0mself[0m[0;34m)[0m[0;34m:[0m[0;34m[0m[0;34m[0m[0m

[0;31mTypeError[0m: __init__() got an unexpected keyword argument 'user'
TypeError: __init__() got an unexpected keyword argument 'user'

