Traceback (most recent call last):
  File "/usr/local/lib/python3.8/dist-packages/jupyter_cache/executors/utils.py", line 51, in single_nb_execution
    executenb(
  File "/usr/local/lib/python3.8/dist-packages/nbclient/client.py", line 1112, in execute
    return NotebookClient(nb=nb, resources=resources, km=km, **kwargs).execute()
  File "/usr/local/lib/python3.8/dist-packages/nbclient/util.py", line 74, in wrapped
    return just_run(coro(*args, **kwargs))
  File "/usr/local/lib/python3.8/dist-packages/nbclient/util.py", line 53, in just_run
    return loop.run_until_complete(coro)
  File "/usr/lib/python3.8/asyncio/base_events.py", line 616, in run_until_complete
    return future.result()
  File "/usr/local/lib/python3.8/dist-packages/nbclient/client.py", line 553, in async_execute
    await self.async_execute_cell(
  File "/usr/local/lib/python3.8/dist-packages/nbclient/client.py", line 857, in async_execute_cell
    self._check_raise_for_error(cell, exec_reply)
  File "/usr/local/lib/python3.8/dist-packages/nbclient/client.py", line 760, in _check_raise_for_error
    raise CellExecutionError.from_cell_and_msg(cell, exec_reply_content)
nbclient.exceptions.CellExecutionError: An error occurred while executing the following cell:
------------------
ds_broad_irr = cat['P5']['BROADBAND_IRRADIANCE']['AFLUX_P5_RF03'].to_dask()
import xarray as xr
xr.set_options(display_expand_attrs=False)  
ds_broad_irr
------------------

[0;31m---------------------------------------------------------------------------[0m
[0;31mValueError[0m                                Traceback (most recent call last)
[0;32m<ipython-input-3-c3bba76c7d28>[0m in [0;36m<module>[0;34m[0m
[1;32m      1[0m [0mds_broad_irr[0m [0;34m=[0m [0mcat[0m[0;34m[[0m[0;34m'P5'[0m[0;34m][0m[0;34m[[0m[0;34m'BROADBAND_IRRADIANCE'[0m[0;34m][0m[0;34m[[0m[0;34m'AFLUX_P5_RF03'[0m[0;34m][0m[0;34m.[0m[0mto_dask[0m[0;34m([0m[0;34m)[0m[0;34m[0m[0;34m[0m[0m
[1;32m      2[0m [0;32mimport[0m [0mxarray[0m [0;32mas[0m [0mxr[0m[0;34m[0m[0;34m[0m[0m
[0;32m----> 3[0;31m [0mxr[0m[0;34m.[0m[0mset_options[0m[0;34m([0m[0mdisplay_expand_attrs[0m[0;34m=[0m[0;32mFalse[0m[0;34m)[0m[0;34m[0m[0;34m[0m[0m
[0m[1;32m      4[0m [0mds_broad_irr[0m[0;34m[0m[0;34m[0m[0m

[0;32m/usr/local/lib/python3.8/dist-packages/xarray/core/options.py[0m in [0;36m__init__[0;34m(self, **kwargs)[0m
[1;32m    133[0m         [0;32mfor[0m [0mk[0m[0;34m,[0m [0mv[0m [0;32min[0m [0mkwargs[0m[0;34m.[0m[0mitems[0m[0;34m([0m[0;34m)[0m[0;34m:[0m[0;34m[0m[0;34m[0m[0m
[1;32m    134[0m             [0;32mif[0m [0mk[0m [0;32mnot[0m [0;32min[0m [0mOPTIONS[0m[0;34m:[0m[0;34m[0m[0;34m[0m[0m
[0;32m--> 135[0;31m                 raise ValueError(
[0m[1;32m    136[0m                     [0;34m"argument name %r is not in the set of valid options %r"[0m[0;34m[0m[0;34m[0m[0m
[1;32m    137[0m                     [0;34m%[0m [0;34m([0m[0mk[0m[0;34m,[0m [0mset[0m[0;34m([0m[0mOPTIONS[0m[0;34m)[0m[0;34m)[0m[0;34m[0m[0;34m[0m[0m

[0;31mValueError[0m: argument name 'display_expand_attrs' is not in the set of valid options {'enable_cftimeindex', 'cmap_sequential', 'file_cache_maxsize', 'keep_attrs', 'arithmetic_join', 'warn_for_unclosed_files', 'cmap_divergent', 'display_style', 'display_max_rows', 'display_width'}
ValueError: argument name 'display_expand_attrs' is not in the set of valid options {'enable_cftimeindex', 'cmap_sequential', 'file_cache_maxsize', 'keep_attrs', 'arithmetic_join', 'warn_for_unclosed_files', 'cmap_divergent', 'display_style', 'display_max_rows', 'display_width'}

