Traceback (most recent call last):
  File "/home/nrisse/anaconda3/envs/pyac3airborne/lib/python3.9/site-packages/jupyter_cache/executors/utils.py", line 51, in single_nb_execution
    executenb(
  File "/home/nrisse/anaconda3/envs/pyac3airborne/lib/python3.9/site-packages/nbclient/client.py", line 1112, in execute
    return NotebookClient(nb=nb, resources=resources, km=km, **kwargs).execute()
  File "/home/nrisse/anaconda3/envs/pyac3airborne/lib/python3.9/site-packages/nbclient/util.py", line 74, in wrapped
    return just_run(coro(*args, **kwargs))
  File "/home/nrisse/anaconda3/envs/pyac3airborne/lib/python3.9/site-packages/nbclient/util.py", line 53, in just_run
    return loop.run_until_complete(coro)
  File "/home/nrisse/anaconda3/envs/pyac3airborne/lib/python3.9/asyncio/base_events.py", line 642, in run_until_complete
    return future.result()
  File "/home/nrisse/anaconda3/envs/pyac3airborne/lib/python3.9/site-packages/nbclient/client.py", line 553, in async_execute
    await self.async_execute_cell(
  File "/home/nrisse/anaconda3/envs/pyac3airborne/lib/python3.9/site-packages/nbclient/client.py", line 857, in async_execute_cell
    self._check_raise_for_error(cell, exec_reply)
  File "/home/nrisse/anaconda3/envs/pyac3airborne/lib/python3.9/site-packages/nbclient/client.py", line 760, in _check_raise_for_error
    raise CellExecutionError.from_cell_and_msg(cell, exec_reply_content)
nbclient.exceptions.CellExecutionError: An error occurred while executing the following cell:
------------------
%matplotlib inline
import matplotlib.pyplot as plt
import matplotlib.dates as mdates
from numpy import log10
plt.style.use("./mplstyle/book")
------------------

[0;31m---------------------------------------------------------------------------[0m
[0;31mFileNotFoundError[0m                         Traceback (most recent call last)
[0;32m~/anaconda3/envs/pyac3airborne/lib/python3.9/site-packages/matplotlib/style/core.py[0m in [0;36muse[0;34m(style)[0m
[1;32m    114[0m             [0;32mtry[0m[0;34m:[0m[0;34m[0m[0;34m[0m[0m
[0;32m--> 115[0;31m                 [0mrc[0m [0;34m=[0m [0mrc_params_from_file[0m[0;34m([0m[0mstyle[0m[0;34m,[0m [0muse_default_template[0m[0;34m=[0m[0;32mFalse[0m[0;34m)[0m[0;34m[0m[0;34m[0m[0m
[0m[1;32m    116[0m                 [0m_apply_style[0m[0;34m([0m[0mrc[0m[0;34m)[0m[0;34m[0m[0;34m[0m[0m

[0;32m~/anaconda3/envs/pyac3airborne/lib/python3.9/site-packages/matplotlib/__init__.py[0m in [0;36mrc_params_from_file[0;34m(fname, fail_on_error, use_default_template)[0m
[1;32m    795[0m     """
[0;32m--> 796[0;31m     [0mconfig_from_file[0m [0;34m=[0m [0m_rc_params_in_file[0m[0;34m([0m[0mfname[0m[0;34m,[0m [0mfail_on_error[0m[0;34m=[0m[0mfail_on_error[0m[0;34m)[0m[0;34m[0m[0;34m[0m[0m
[0m[1;32m    797[0m [0;34m[0m[0m

[0;32m~/anaconda3/envs/pyac3airborne/lib/python3.9/site-packages/matplotlib/__init__.py[0m in [0;36m_rc_params_in_file[0;34m(fname, transform, fail_on_error)[0m
[1;32m    724[0m     [0mrc_temp[0m [0;34m=[0m [0;34m{[0m[0;34m}[0m[0;34m[0m[0;34m[0m[0m
[0;32m--> 725[0;31m     [0;32mwith[0m [0m_open_file_or_url[0m[0;34m([0m[0mfname[0m[0;34m)[0m [0;32mas[0m [0mfd[0m[0;34m:[0m[0;34m[0m[0;34m[0m[0m
[0m[1;32m    726[0m         [0;32mtry[0m[0;34m:[0m[0;34m[0m[0;34m[0m[0m

[0;32m~/anaconda3/envs/pyac3airborne/lib/python3.9/contextlib.py[0m in [0;36m__enter__[0;34m(self)[0m
[1;32m    116[0m         [0;32mtry[0m[0;34m:[0m[0;34m[0m[0;34m[0m[0m
[0;32m--> 117[0;31m             [0;32mreturn[0m [0mnext[0m[0;34m([0m[0mself[0m[0;34m.[0m[0mgen[0m[0;34m)[0m[0;34m[0m[0;34m[0m[0m
[0m[1;32m    118[0m         [0;32mexcept[0m [0mStopIteration[0m[0;34m:[0m[0;34m[0m[0;34m[0m[0m

[0;32m~/anaconda3/envs/pyac3airborne/lib/python3.9/site-packages/matplotlib/__init__.py[0m in [0;36m_open_file_or_url[0;34m(fname)[0m
[1;32m    702[0m             [0mencoding[0m [0;34m=[0m [0;34m"utf-8"[0m[0;34m[0m[0;34m[0m[0m
[0;32m--> 703[0;31m         [0;32mwith[0m [0mopen[0m[0;34m([0m[0mfname[0m[0;34m,[0m [0mencoding[0m[0;34m=[0m[0mencoding[0m[0;34m)[0m [0;32mas[0m [0mf[0m[0;34m:[0m[0;34m[0m[0;34m[0m[0m
[0m[1;32m    704[0m             [0;32myield[0m [0mf[0m[0;34m[0m[0;34m[0m[0m

[0;31mFileNotFoundError[0m: [Errno 2] No such file or directory: './mplstyle/book'

The above exception was the direct cause of the following exception:

[0;31mOSError[0m                                   Traceback (most recent call last)
[0;32m<ipython-input-8-eaf0735f728b>[0m in [0;36m<module>[0;34m[0m
[1;32m      3[0m [0;32mimport[0m [0mmatplotlib[0m[0;34m.[0m[0mdates[0m [0;32mas[0m [0mmdates[0m[0;34m[0m[0;34m[0m[0m
[1;32m      4[0m [0;32mfrom[0m [0mnumpy[0m [0;32mimport[0m [0mlog10[0m[0;34m[0m[0;34m[0m[0m
[0;32m----> 5[0;31m [0mplt[0m[0;34m.[0m[0mstyle[0m[0;34m.[0m[0muse[0m[0;34m([0m[0;34m"./mplstyle/book"[0m[0;34m)[0m[0;34m[0m[0;34m[0m[0m
[0m
[0;32m~/anaconda3/envs/pyac3airborne/lib/python3.9/site-packages/matplotlib/style/core.py[0m in [0;36muse[0;34m(style)[0m
[1;32m    116[0m                 [0m_apply_style[0m[0;34m([0m[0mrc[0m[0;34m)[0m[0;34m[0m[0;34m[0m[0m
[1;32m    117[0m             [0;32mexcept[0m [0mIOError[0m [0;32mas[0m [0merr[0m[0;34m:[0m[0;34m[0m[0;34m[0m[0m
[0;32m--> 118[0;31m                 raise IOError(
[0m[1;32m    119[0m                     [0;34m"{!r} not found in the style library and input is not a "[0m[0;34m[0m[0;34m[0m[0m
[1;32m    120[0m                     [0;34m"valid URL or path; see `style.available` for list of "[0m[0;34m[0m[0;34m[0m[0m

[0;31mOSError[0m: './mplstyle/book' not found in the style library and input is not a valid URL or path; see `style.available` for list of available styles
OSError: './mplstyle/book' not found in the style library and input is not a valid URL or path; see `style.available` for list of available styles

